Workbook

Sheet Vejledning
B1: NIS2 Risikovurdering og risikostyring
B2: Skabelon til systematisk risikovurdering efter NIS2-lovens § 6, stk. 1, nr. 1 · Udviklet af Kasper Mensink
B4: OM VÆRKTØJET
B5: Skabelonen understøtter enheder omfattet af NIS2-loven (Lov om foranstaltninger til sikring af et højt cybersikkerhedsniveau) i at gennemføre og dokumentere en systematisk risikovurdering. Den er sektorneutral og kan tilpasses enhver organisation. Med skabelonen kan I: • Gennemføre en struktureret risikovurdering af jeres net- og informationssystemer • Dokumentere risikostyringen i overensstemmelse med NIS2 • Identificere og prioritere de foranstaltninger, I skal implementere • Skabe grundlag for ledelsens godkendelse af risikovurdering, risikohåndtering og restrisici
B7: PROCESSEN
B8: → | C8: 1 Lav en risikostyringspolitik | D8: 2 Gennemfør risikovurderingen | E8: 3 Godkend hos ledelsen | F8: 4 Implementér og følg op | G8: 5 Genbesøg
C9: Fastlæg rammer, kriterier og roller. | D9: Vurdér sandsynlighed, konsekvens og validitet. | E9: Ledelsesorganet godkender resultat og restrisici. | F9: Gennemfør foranstaltninger og følg fremdriften. | G9: Revurdér mindst årligt og ved væsentlige ændringer.
B11: SÅDAN BRUGER I SKABELONEN
B12: 1 | C12: Læs og tilpas risikostyringspolitikken | D12: Tag udgangspunkt i fanen "Eksempel - Politik" og tilpas den til jeres organisation. Resultatet af risikovurderingen, den planlagte risikohåndtering og niveauet af de tilbageværende risici skal accepteres af risikoejeren, primært i relation til samfundsrisici, med passende rapportering til enhedens ledelsesorgan.
B13: 2 | C13: Gennemfør risikovurderingen | D13: Udfyld fanen "Risikovurdering". Gennemgå hver risikokategori, vurdér sandsynlighed (1-5) og konsekvens (1-5), dokumentér begrundelserne, angiv vurderingens validitet (1-3), beskriv eksisterende og planlagte foranstaltninger, og udpeg ansvarlige. Brug gerne trussel-ID'er fra fanen "Trusselskatalog".
B14: 3 | C14: Godkend hos ledelsen | D14: Præsentér resultatet og risikohåndteringsplanen for ledelsesorganet, og få det godkendt formelt, f.eks. med underskrift. Fanen "Risikomatrix" giver et samlet overblik til ledelsesrapporteringen.
B15: 4 | C15: Implementér og følg op | D15: Implementér de planlagte foranstaltninger, overvåg fremdriften, revurdér risici ved relevante ændringer, opdatér dokumentationen løbende og rapportér til ledelsen.
B16: 5 | C16: Genbesøg | D16: Politik og risikovurdering er levende dokumenter. De skal revideres mindst én gang årligt og opdateres ved væsentlige ændringer i forretning, trusselsbillede eller sårbarheder.
B18: Vigtigt: Aktiver, risici og vurderinger i eksempelfanerne er vejledende og beskriver en fiktiv virksomhed. Virksomheden skal altid tilpasse dem, så de afspejler egen organisation, it-miljø, forretningsmodel, trusselsbillede og modenhedsniveau.
B20: FANER I PROJEKTMAPPEN
C21: Vejledning | D21: Formål, proces, skalaer og definitioner.
C22: Risikovurdering | D22: Skabelonen, der udfyldes. Hvide felter er inputfelter; grå felter beregnes automatisk.
C23: Risikomatrix | D23: Samlet overblik: 5×5 risikomatrix, fordeling på risikoniveau før og efter foranstaltninger og nøgletal pr. kategori. Vælg i fanen, om overblikket skal vise jeres egen vurdering eller eksemplet.
C24: Trusselskatalog | D24: Forslag til trusler og sårbarheder fordelt på de seks risikokategorier, med trussel-ID.
C25: Eksempel - Politik | D25: Eksempel på en politik for risikostyring, der kan tilpasses.
C26: Eksempel - Risikovurdering | D26: Udfyldt eksempel for en fiktiv mellemstor virksomhed, der viser det forventede detaljeniveau.
B28: DE 10 FORANSTALTNINGER I NIS2-LOVENS § 6, STK. 1
B29: Nr. | C29: Foranstaltning | D29: Beskrivelse
B30: 1 | C30: Politik for risikoanalyse og informationssystemsikkerhed | D30: Etablér politikker for at identificere, analysere og håndtere risici. Gennemfør regelmæssige risikovurderinger.
B31: 2 | C31: Håndtering af hændelser | D31: Etablér procedurer for at opdage, rapportere og håndtere sikkerhedshændelser. Implementér logging og monitorering.
B32: 3 | C32: Driftskontinuitet | D32: Sikr backup, redundans og evne til at gendanne drift efter hændelser. Udarbejd krisestyringsplaner.
B33: 4 | C33: Forsyningskædesikkerhed | D33: Vurdér og håndter cybersikkerhedsrisici fra leverandører og tjenesteudbydere.
B34: 5 | C34: Sikkerhed ved erhvervelse, udvikling og vedligeholdelse | D34: Sikr sikkerhed gennem hele livscyklus for systemer. Håndtér sårbarheder systematisk.
B35: 6 | C35: Vurdering af effektivitet | D35: Evaluér regelmæssigt om foranstaltningerne er tilstrækkelige og effektive.
B36: 7 | C36: Cyberhygiejne og uddannelse | D36: Træn medarbejdere i cybersikkerhed og etablér god sikkerhedspraksis.
B37: 8 | C37: Kryptografi og kryptering | D37: Anvend kryptering til at beskytte fortrolige data hvor relevant.
B38: 9 | C38: Personalesikkerhed og adgangskontrol | D38: Kontrollér adgang til systemer og data. Forvalt brugerrettigheder og assets.
B39: 10 | C39: Autentificering og sikker kommunikation | D39: Implementér multifaktorautentificering og sikre kommunikationskanaler.
B41: SANDSYNLIGHED – HVOR SANDSYNLIGT ER DET, AT RISIKOEN INDTRÆFFER INDEN FOR ET ÅR?
B42: 1 | C42: Usandsynlig | D42: Risikokilden har meget lille sandsynlighed for at nå sit mål ved at anvende en af de identificerede trusler/sårbarheder.
B43: 2 | C43: Ret usandsynlig | D43: Risikokilden har relativt lille sandsynlighed for at nå sit mål ved at anvende en af de identificerede trusler/sårbarheder.
B44: 3 | C44: Sandsynlig | D44: Risikokilden er i stand til at nå sit mål ved at anvende en af de identificerede trusler/sårbarheder.
B45: 4 | C45: Meget sandsynlig | D45: Risikokilden vil sandsynligvis nå sit mål ved at anvende en af de identificerede trusler/sårbarheder.
B46: 5 | C46: Næsten sikker | D46: Risikokilden vil med stor sikkerhed nå sit mål ved at anvende en af de identificerede trusler/sårbarheder.
B48: KONSEKVENS – HVOR ALVORLIG ER KONSEKVENSEN, HVIS RISIKOEN INDTRÆFFER?
...

Sheet Risikovurdering
A1: Risikovurdering og risikohåndtering
A2: NIS2-lovens § 6, stk. 1, nr. 1 · Udfyld én række pr. risiko, og tilføj rækker efter behov
A3: Virksomhed | E3: Udarbejdet af | I3: Dato | M3: Godkendt af ledelsen (navn/dato) | P3: Version | R3: Hvide felter udfyldes · Grå felter beregnes automatisk
A5: RISIKOVURDERING | M5: RISIKOHÅNDTERING
A6: Risikoområde / aktiv | B6: Trussel / sårbarhed | C6: Risikoejer | D6: Beskrivelse af risiko (hvad kan gå galt?) | E6: Sandsyn- lighed (1-5) | F6: Begrundelse for sandsynlighed (inden for et år) | G6: Konse- kvens (1-5) | H6: Begrundelse for konsekvens | I6: Risiko- score (S×K) | J6: Risiko- niveau | K6: Validitet (1-3) | L6: Accepteres risikoen? | M6: Eksisterende foranstaltninger | N6: Ansvarlig for implementering | O6: Restrisiko (1-25) | P6: Restrisiko- niveau | Q6: Accepteres restrisikoen? | R6: Planlagte foranstaltninger (inden for et år) | S6: Dokumen- tation? | T6: Bemærkninger til vurdering
A7: 1. NET- OG INFORMATIONSSYSTEMER
I8: =IF(OR(E8="",G8=""),"",E8*G8) | J8: =IF(I8="","",IF(I8<5,"Lav",IF(I8<10,"Middel","Høj"))) | P8: =IF(O8="","",IF(O8<5,"Lav",IF(O8<10,"Middel","Høj")))
I9: =IF(OR(E9="",G9=""),"",E9*G9) | J9: =IF(I9="","",IF(I9<5,"Lav",IF(I9<10,"Middel","Høj"))) | P9: =IF(O9="","",IF(O9<5,"Lav",IF(O9<10,"Middel","Høj")))
I10: =IF(OR(E10="",G10=""),"",E10*G10) | J10: =IF(I10="","",IF(I10<5,"Lav",IF(I10<10,"Middel","Høj"))) | P10: =IF(O10="","",IF(O10<5,"Lav",IF(O10<10,"Middel","Høj")))
I11: =IF(OR(E11="",G11=""),"",E11*G11) | J11: =IF(I11="","",IF(I11<5,"Lav",IF(I11<10,"Middel","Høj"))) | P11: =IF(O11="","",IF(O11<5,"Lav",IF(O11<10,"Middel","Høj")))
I12: =IF(OR(E12="",G12=""),"",E12*G12) | J12: =IF(I12="","",IF(I12<5,"Lav",IF(I12<10,"Middel","Høj"))) | P12: =IF(O12="","",IF(O12<5,"Lav",IF(O12<10,"Middel","Høj")))
I13: =IF(OR(E13="",G13=""),"",E13*G13) | J13: =IF(I13="","",IF(I13<5,"Lav",IF(I13<10,"Middel","Høj"))) | P13: =IF(O13="","",IF(O13<5,"Lav",IF(O13<10,"Middel","Høj")))
I14: =IF(OR(E14="",G14=""),"",E14*G14) | J14: =IF(I14="","",IF(I14<5,"Lav",IF(I14<10,"Middel","Høj"))) | P14: =IF(O14="","",IF(O14<5,"Lav",IF(O14<10,"Middel","Høj")))
I15: =IF(OR(E15="",G15=""),"",E15*G15) | J15: =IF(I15="","",IF(I15<5,"Lav",IF(I15<10,"Middel","Høj"))) | P15: =IF(O15="","",IF(O15<5,"Lav",IF(O15<10,"Middel","Høj")))
A16: 2. APPLIKATIONER OG TJENESTER
I17: =IF(OR(E17="",G17=""),"",E17*G17) | J17: =IF(I17="","",IF(I17<5,"Lav",IF(I17<10,"Middel","Høj"))) | P17: =IF(O17="","",IF(O17<5,"Lav",IF(O17<10,"Middel","Høj")))
I18: =IF(OR(E18="",G18=""),"",E18*G18) | J18: =IF(I18="","",IF(I18<5,"Lav",IF(I18<10,"Middel","Høj"))) | P18: =IF(O18="","",IF(O18<5,"Lav",IF(O18<10,"Middel","Høj")))
I19: =IF(OR(E19="",G19=""),"",E19*G19) | J19: =IF(I19="","",IF(I19<5,"Lav",IF(I19<10,"Middel","Høj"))) | P19: =IF(O19="","",IF(O19<5,"Lav",IF(O19<10,"Middel","Høj")))
I20: =IF(OR(E20="",G20=""),"",E20*G20) | J20: =IF(I20="","",IF(I20<5,"Lav",IF(I20<10,"Middel","Høj"))) | P20: =IF(O20="","",IF(O20<5,"Lav",IF(O20<10,"Middel","Høj")))
I21: =IF(OR(E21="",G21=""),"",E21*G21) | J21: =IF(I21="","",IF(I21<5,"Lav",IF(I21<10,"Middel","Høj"))) | P21: =IF(O21="","",IF(O21<5,"Lav",IF(O21<10,"Middel","Høj")))
I22: =IF(OR(E22="",G22=""),"",E22*G22) | J22: =IF(I22="","",IF(I22<5,"Lav",IF(I22<10,"Middel","Høj"))) | P22: =IF(O22="","",IF(O22<5,"Lav",IF(O22<10,"Middel","Høj")))
I23: =IF(OR(E23="",G23=""),"",E23*G23) | J23: =IF(I23="","",IF(I23<5,"Lav",IF(I23<10,"Middel","Høj"))) | P23: =IF(O23="","",IF(O23<5,"Lav",IF(O23<10,"Middel","Høj")))
I24: =IF(OR(E24="",G24=""),"",E24*G24) | J24: =IF(I24="","",IF(I24<5,"Lav",IF(I24<10,"Middel","Høj"))) | P24: =IF(O24="","",IF(O24<5,"Lav",IF(O24<10,"Middel","Høj")))
A25: 3. DATA OG INFORMATIONSAKTIVER
I26: =IF(OR(E26="",G26=""),"",E26*G26) | J26: =IF(I26="","",IF(I26<5,"Lav",IF(I26<10,"Middel","Høj"))) | P26: =IF(O26="","",IF(O26<5,"Lav",IF(O26<10,"Middel","Høj")))
I27: =IF(OR(E27="",G27=""),"",E27*G27) | J27: =IF(I27="","",IF(I27<5,"Lav",IF(I27<10,"Middel","Høj"))) | P27: =IF(O27="","",IF(O27<5,"Lav",IF(O27<10,"Middel","Høj")))
I28: =IF(OR(E28="",G28=""),"",E28*G28) | J28: =IF(I28="","",IF(I28<5,"Lav",IF(I28<10,"Middel","Høj"))) | P28: =IF(O28="","",IF(O28<5,"Lav",IF(O28<10,"Middel","Høj")))
I29: =IF(OR(E29="",G29=""),"",E29*G29) | J29: =IF(I29="","",IF(I29<5,"Lav",IF(I29<10,"Middel","Høj"))) | P29: =IF(O29="","",IF(O29<5,"Lav",IF(O29<10,"Middel","Høj")))
I30: =IF(OR(E30="",G30=""),"",E30*G30) | J30: =IF(I30="","",IF(I30<5,"Lav",IF(I30<10,"Middel","Høj"))) | P30: =IF(O30="","",IF(O30<5,"Lav",IF(O30<10,"Middel","Høj")))
I31: =IF(OR(E31="",G31=""),"",E31*G31) | J31: =IF(I31="","",IF(I31<5,"Lav",IF(I31<10,"Middel","Høj"))) | P31: =IF(O31="","",IF(O31<5,"Lav",IF(O31<10,"Middel","Høj")))
I32: =IF(OR(E32="",G32=""),"",E32*G32) | J32: =IF(I32="","",IF(I32<5,"Lav",IF(I32<10,"Middel","Høj"))) | P32: =IF(O32="","",IF(O32<5,"Lav",IF(O32<10,"Middel","Høj")))
I33: =IF(OR(E33="",G33=""),"",E33*G33) | J33: =IF(I33="","",IF(I33<5,"Lav",IF(I33<10,"Middel","Høj"))) | P33: =IF(O33="","",IF(O33<5,"Lav",IF(O33<10,"Middel","Høj")))
A34: 4. MEDARBEJDERE OG PROCESSER
I35: =IF(OR(E35="",G35=""),"",E35*G35) | J35: =IF(I35="","",IF(I35<5,"Lav",IF(I35<10,"Middel","Høj"))) | P35: =IF(O35="","",IF(O35<5,"Lav",IF(O35<10,"Middel","Høj")))
I36: =IF(OR(E36="",G36=""),"",E36*G36) | J36: =IF(I36="","",IF(I36<5,"Lav",IF(I36<10,"Middel","Høj"))) | P36: =IF(O36="","",IF(O36<5,"Lav",IF(O36<10,"Middel","Høj")))
I37: =IF(OR(E37="",G37=""),"",E37*G37) | J37: =IF(I37="","",IF(I37<5,"Lav",IF(I37<10,"Middel","Høj"))) | P37: =IF(O37="","",IF(O37<5,"Lav",IF(O37<10,"Middel","Høj")))
I38: =IF(OR(E38="",G38=""),"",E38*G38) | J38: =IF(I38="","",IF(I38<5,"Lav",IF(I38<10,"Middel","Høj"))) | P38: =IF(O38="","",IF(O38<5,"Lav",IF(O38<10,"Middel","Høj")))
I39: =IF(OR(E39="",G39=""),"",E39*G39) | J39: =IF(I39="","",IF(I39<5,"Lav",IF(I39<10,"Middel","Høj"))) | P39: =IF(O39="","",IF(O39<5,"Lav",IF(O39<10,"Middel","Høj")))
I40: =IF(OR(E40="",G40=""),"",E40*G40) | J40: =IF(I40="","",IF(I40<5,"Lav",IF(I40<10,"Middel","Høj"))) | P40: =IF(O40="","",IF(O40<5,"Lav",IF(O40<10,"Middel","Høj")))
I41: =IF(OR(E41="",G41=""),"",E41*G41) | J41: =IF(I41="","",IF(I41<5,"Lav",IF(I41<10,"Middel","Høj"))) | P41: =IF(O41="","",IF(O41<5,"Lav",IF(O41<10,"Middel","Høj")))
...

Sheet Risikomatrix
B1: Risikomatrix og overblik
B2: Opdateres automatisk ud fra den valgte risikovurdering
B4: Vis data fra: | C4: Eksempel | F4: ← vælg "Risikovurdering" for at se jeres egen vurdering
B6: RISIKOMATRIX – ANTAL RISICI (FØR FORANSTALTNINGER) | J6: FORDELING PÅ RISIKONIVEAU
J8: Risikoniveau | K8: Før | L8: Efter | M8: Ændring
B9: S A N D S Y N L I G H E D ↑ | C9: 5 Næsten sikker | D9: =IF($C$4="Eksempel",COUNTIFS('Eksempel - Risikovurdering'!$E$7:$E$37,5,'Eksempel - Risikovurdering'!$G$7:$G$37,1),COUNTIFS(Risikovurdering!$E$7:$E$60,5,Risikovurdering!$G$7:$G$60,1)) -> 0 | E9: =IF($C$4="Eksempel",COUNTIFS('Eksempel - Risikovurdering'!$E$7:$E$37,5,'Eksempel - Risikovurdering'!$G$7:$G$37,2),COUNTIFS(Risikovurdering!$E$7:$E$60,5,Risikovurdering!$G$7:$G$60,2)) -> 0 | F9: =IF($C$4="Eksempel",COUNTIFS('Eksempel - Risikovurdering'!$E$7:$E$37,5,'Eksempel - Risikovurdering'!$G$7:$G$37,3),COUNTIFS(Risikovurdering!$E$7:$E$60,5,Risikovurdering!$G$7:$G$60,3)) -> 0 | G9: =IF($C$4="Eksempel",COUNTIFS('Eksempel - Risikovurdering'!$E$7:$E$37,5,'Eksempel - Risikovurdering'!$G$7:$G$37,4),COUNTIFS(Risikovurdering!$E$7:$E$60,5,Risikovurdering!$G$7:$G$60,4)) -> 0 | H9: =IF($C$4="Eksempel",COUNTIFS('Eksempel - Risikovurdering'!$E$7:$E$37,5,'Eksempel - Risikovurdering'!$G$7:$G$37,5),COUNTIFS(Risikovurdering!$E$7:$E$60,5,Risikovurdering!$G$7:$G$60,5)) -> 0 | J9: Høj (10-25) | K9: =IF($C$4="Eksempel",COUNTIFS('Eksempel - Risikovurdering'!$I$7:$I$37,">=10",'Eksempel - Risikovurdering'!$I$7:$I$37,"<=25"),COUNTIFS(Risikovurdering!$I$7:$I$60,">=10",Risikovurdering!$I$7:$I$60,"<=25")) -> 9 | L9: =IF($C$4="Eksempel",COUNTIFS('Eksempel - Risikovurdering'!$O$7:$O$37,">=10",'Eksempel - Risikovurdering'!$O$7:$O$37,"<=25"),COUNTIFS(Risikovurdering!$O$7:$O$60,">=10",Risikovurdering!$O$7:$O$60,"<=25")) -> 0 | M9: =L9-K9 -> -9
C10: 4 Meget sandsynlig | D10: =IF($C$4="Eksempel",COUNTIFS('Eksempel - Risikovurdering'!$E$7:$E$37,4,'Eksempel - Risikovurdering'!$G$7:$G$37,1),COUNTIFS(Risikovurdering!$E$7:$E$60,4,Risikovurdering!$G$7:$G$60,1)) -> 0 | E10: =IF($C$4="Eksempel",COUNTIFS('Eksempel - Risikovurdering'!$E$7:$E$37,4,'Eksempel - Risikovurdering'!$G$7:$G$37,2),COUNTIFS(Risikovurdering!$E$7:$E$60,4,Risikovurdering!$G$7:$G$60,2)) -> 0 | F10: =IF($C$4="Eksempel",COUNTIFS('Eksempel - Risikovurdering'!$E$7:$E$37,4,'Eksempel - Risikovurdering'!$G$7:$G$37,3),COUNTIFS(Risikovurdering!$E$7:$E$60,4,Risikovurdering!$G$7:$G$60,3)) -> 1 | G10: =IF($C$4="Eksempel",COUNTIFS('Eksempel - Risikovurdering'!$E$7:$E$37,4,'Eksempel - Risikovurdering'!$G$7:$G$37,4),COUNTIFS(Risikovurdering!$E$7:$E$60,4,Risikovurdering!$G$7:$G$60,4)) -> 0 | H10: =IF($C$4="Eksempel",COUNTIFS('Eksempel - Risikovurdering'!$E$7:$E$37,4,'Eksempel - Risikovurdering'!$G$7:$G$37,5),COUNTIFS(Risikovurdering!$E$7:$E$60,4,Risikovurdering!$G$7:$G$60,5)) -> 0 | J10: Middel (5-9) | K10: =IF($C$4="Eksempel",COUNTIFS('Eksempel - Risikovurdering'!$I$7:$I$37,">=5",'Eksempel - Risikovurdering'!$I$7:$I$37,"<10"),COUNTIFS(Risikovurdering!$I$7:$I$60,">=5",Risikovurdering!$I$7:$I$60,"<10")) -> 15 | L10: =IF($C$4="Eksempel",COUNTIFS('Eksempel - Risikovurdering'!$O$7:$O$37,">=5",'Eksempel - Risikovurdering'!$O$7:$O$37,"<10"),COUNTIFS(Risikovurdering!$O$7:$O$60,">=5",Risikovurdering!$O$7:$O$60,"<10")) -> 10 | M10: =L10-K10 -> -5
C11: 3 Sandsynlig | D11: =IF($C$4="Eksempel",COUNTIFS('Eksempel - Risikovurdering'!$E$7:$E$37,3,'Eksempel - Risikovurdering'!$G$7:$G$37,1),COUNTIFS(Risikovurdering!$E$7:$E$60,3,Risikovurdering!$G$7:$G$60,1)) -> 0 | E11: =IF($C$4="Eksempel",COUNTIFS('Eksempel - Risikovurdering'!$E$7:$E$37,3,'Eksempel - Risikovurdering'!$G$7:$G$37,2),COUNTIFS(Risikovurdering!$E$7:$E$60,3,Risikovurdering!$G$7:$G$60,2)) -> 0 | F11: =IF($C$4="Eksempel",COUNTIFS('Eksempel - Risikovurdering'!$E$7:$E$37,3,'Eksempel - Risikovurdering'!$G$7:$G$37,3),COUNTIFS(Risikovurdering!$E$7:$E$60,3,Risikovurdering!$G$7:$G$60,3)) -> 5 | G11: =IF($C$4="Eksempel",COUNTIFS('Eksempel - Risikovurdering'!$E$7:$E$37,3,'Eksempel - Risikovurdering'!$G$7:$G$37,4),COUNTIFS(Risikovurdering!$E$7:$E$60,3,Risikovurdering!$G$7:$G$60,4)) -> 3 | H11: =IF($C$4="Eksempel",COUNTIFS('Eksempel - Risikovurdering'!$E$7:$E$37,3,'Eksempel - Risikovurdering'!$G$7:$G$37,5),COUNTIFS(Risikovurdering!$E$7:$E$60,3,Risikovurdering!$G$7:$G$60,5)) -> 1 | J11: Lav (1-4) | K11: =IF($C$4="Eksempel",COUNTIFS('Eksempel - Risikovurdering'!$I$7:$I$37,">=1",'Eksempel - Risikovurdering'!$I$7:$I$37,"<5"),COUNTIFS(Risikovurdering!$I$7:$I$60,">=1",Risikovurdering!$I$7:$I$60,"<5")) -> 1 | L11: =IF($C$4="Eksempel",COUNTIFS('Eksempel - Risikovurdering'!$O$7:$O$37,">=1",'Eksempel - Risikovurdering'!$O$7:$O$37,"<5"),COUNTIFS(Risikovurdering!$O$7:$O$60,">=1",Risikovurdering!$O$7:$O$60,"<5")) -> 15 | M11: =L11-K11 -> 14
C12: 2 Ret usandsynlig | D12: =IF($C$4="Eksempel",COUNTIFS('Eksempel - Risikovurdering'!$E$7:$E$37,2,'Eksempel - Risikovurdering'!$G$7:$G$37,1),COUNTIFS(Risikovurdering!$E$7:$E$60,2,Risikovurdering!$G$7:$G$60,1)) -> 0 | E12: =IF($C$4="Eksempel",COUNTIFS('Eksempel - Risikovurdering'!$E$7:$E$37,2,'Eksempel - Risikovurdering'!$G$7:$G$37,2),COUNTIFS(Risikovurdering!$E$7:$E$60,2,Risikovurdering!$G$7:$G$60,2)) -> 1 | F12: =IF($C$4="Eksempel",COUNTIFS('Eksempel - Risikovurdering'!$E$7:$E$37,2,'Eksempel - Risikovurdering'!$G$7:$G$37,3),COUNTIFS(Risikovurdering!$E$7:$E$60,2,Risikovurdering!$G$7:$G$60,3)) -> 3 | G12: =IF($C$4="Eksempel",COUNTIFS('Eksempel - Risikovurdering'!$E$7:$E$37,2,'Eksempel - Risikovurdering'!$G$7:$G$37,4),COUNTIFS(Risikovurdering!$E$7:$E$60,2,Risikovurdering!$G$7:$G$60,4)) -> 6 | H12: =IF($C$4="Eksempel",COUNTIFS('Eksempel - Risikovurdering'!$E$7:$E$37,2,'Eksempel - Risikovurdering'!$G$7:$G$37,5),COUNTIFS(Risikovurdering!$E$7:$E$60,2,Risikovurdering!$G$7:$G$60,5)) -> 4 | J12: I alt vurderet | K12: =SUM(K9:K11) -> 25 | L12: =SUM(L9:L11) -> 25
C13: 1 Usandsynlig | D13: =IF($C$4="Eksempel",COUNTIFS('Eksempel - Risikovurdering'!$E$7:$E$37,1,'Eksempel - Risikovurdering'!$G$7:$G$37,1),COUNTIFS(Risikovurdering!$E$7:$E$60,1,Risikovurdering!$G$7:$G$60,1)) -> 0 | E13: =IF($C$4="Eksempel",COUNTIFS('Eksempel - Risikovurdering'!$E$7:$E$37,1,'Eksempel - Risikovurdering'!$G$7:$G$37,2),COUNTIFS(Risikovurdering!$E$7:$E$60,1,Risikovurdering!$G$7:$G$60,2)) -> 0 | F13: =IF($C$4="Eksempel",COUNTIFS('Eksempel - Risikovurdering'!$E$7:$E$37,1,'Eksempel - Risikovurdering'!$G$7:$G$37,3),COUNTIFS(Risikovurdering!$E$7:$E$60,1,Risikovurdering!$G$7:$G$60,3)) -> 0 | G13: =IF($C$4="Eksempel",COUNTIFS('Eksempel - Risikovurdering'!$E$7:$E$37,1,'Eksempel - Risikovurdering'!$G$7:$G$37,4),COUNTIFS(Risikovurdering!$E$7:$E$60,1,Risikovurdering!$G$7:$G$60,4)) -> 0 | H13: =IF($C$4="Eksempel",COUNTIFS('Eksempel - Risikovurdering'!$E$7:$E$37,1,'Eksempel - Risikovurdering'!$G$7:$G$37,5),COUNTIFS(Risikovurdering!$E$7:$E$60,1,Risikovurdering!$G$7:$G$60,5)) -> 1 | J13: "Før" er risikoscoren (sandsynlighed × konsekvens). "Efter" er den vurderede restrisiko, når de planlagte foranstaltninger er gennemført.
D14: 1 Ubetydelig | E14: 2 Lille | F14: 3 Moderat | G14: 4 Alvorlig | H14: 5 Katastrofal
D15: K O N S E K V E N S →
B16: Cellerne viser antal risici med den pågældende kombination af sandsynlighed og konsekvens. Farven angiver risikoniveauet: lav (1-4), middel (5-9) og høj (10-25).
B18: NØGLETAL PR. RISIKOKATEGORI
B20: Risikokategori | E20: Antal vurderet | F20: Antal høje | G20: Gns. score | H20: Højeste score | J20: Gns. restrisiko | K20: Høje efter | L20: Ikke accepteret | M20: Dokumentation mangler
B21: 1. Net- og informationssystemer | E21: =IF($C$4="Eksempel",COUNT('Eksempel - Risikovurdering'!$I$8:$I$12),COUNT(Risikovurdering!$I$8:$I$15)) -> 5 | F21: =IF($C$4="Eksempel",COUNTIF('Eksempel - Risikovurdering'!$I$8:$I$12,">=10"),COUNTIF(Risikovurdering!$I$8:$I$15,">=10")) -> 2 | G21: =IF($C$4="Eksempel",IF(COUNT('Eksempel - Risikovurdering'!$I$8:$I$12)=0,"–",AVERAGE('Eksempel - Risikovurdering'!$I$8:$I$12)),IF(COUNT(Risikovurdering!$I$8:$I$15)=0,"–",AVERAGE(Risikovurdering!$I$8:$I$15))) -> 9.4 | H21: =IF($C$4="Eksempel",IF(COUNT('Eksempel - Risikovurdering'!$I$8:$I$12)=0,"–",MAX('Eksempel - Risikovurdering'!$I$8:$I$12)),IF(COUNT(Risikovurdering!$I$8:$I$15)=0,"–",MAX(Risikovurdering!$I$8:$I$15))) -> 12 | J21: =IF($C$4="Eksempel",IF(COUNT('Eksempel - Risikovurdering'!$O$8:$O$12)=0,"–",AVERAGE('Eksempel - Risikovurdering'!$O$8:$O$12)),IF(COUNT(Risikovurdering!$O$8:$O$15)=0,"–",AVERAGE(Risikovurdering!$O$8:$O$15))) -> 4.6 | K21: =IF($C$4="Eksempel",COUNTIF('Eksempel - Risikovurdering'!$O$8:$O$12,">=10"),COUNTIF(Risikovurdering!$O$8:$O$15,">=10")) -> 0 | L21: =IF($C$4="Eksempel",COUNTIF('Eksempel - Risikovurdering'!$Q$8:$Q$12,"Nej"),COUNTIF(Risikovurdering!$Q$8:$Q$15,"Nej")) -> 2 | M21: =IF($C$4="Eksempel",COUNTIFS('Eksempel - Risikovurdering'!$S$8:$S$12,"Nej",'Eksempel - Risikovurdering'!$I$8:$I$12,">0"),COUNTIFS(Risikovurdering!$S$8:$S$15,"Nej",Risikovurdering!$I$8:$I$15,">0")) -> 2
B22: 2. Applikationer og tjenester | E22: =IF($C$4="Eksempel",COUNT('Eksempel - Risikovurdering'!$I$14:$I$17),COUNT(Risikovurdering!$I$17:$I$24)) -> 4 | F22: =IF($C$4="Eksempel",COUNTIF('Eksempel - Risikovurdering'!$I$14:$I$17,">=10"),COUNTIF(Risikovurdering!$I$17:$I$24,">=10")) -> 2 | G22: =IF($C$4="Eksempel",IF(COUNT('Eksempel - Risikovurdering'!$I$14:$I$17)=0,"–",AVERAGE('Eksempel - Risikovurdering'!$I$14:$I$17)),IF(COUNT(Risikovurdering!$I$17:$I$24)=0,"–",AVERAGE(Risikovurdering!$I$17:$I$24))) -> 9.5 | H22: =IF($C$4="Eksempel",IF(COUNT('Eksempel - Risikovurdering'!$I$14:$I$17)=0,"–",MAX('Eksempel - Risikovurdering'!$I$14:$I$17)),IF(COUNT(Risikovurdering!$I$17:$I$24)=0,"–",MAX(Risikovurdering!$I$17:$I$24))) -> 12 | J22: =IF($C$4="Eksempel",IF(COUNT('Eksempel - Risikovurdering'!$O$14:$O$17)=0,"–",AVERAGE('Eksempel - Risikovurdering'!$O$14:$O$17)),IF(COUNT(Risikovurdering!$O$17:$O$24)=0,"–",AVERAGE(Risikovurdering!$O$17:$O$24))) -> 4.75 | K22: =IF($C$4="Eksempel",COUNTIF('Eksempel - Risikovurdering'!$O$14:$O$17,">=10"),COUNTIF(Risikovurdering!$O$17:$O$24,">=10")) -> 0 | L22: =IF($C$4="Eksempel",COUNTIF('Eksempel - Risikovurdering'!$Q$14:$Q$17,"Nej"),COUNTIF(Risikovurdering!$Q$17:$Q$24,"Nej")) -> 0 | M22: =IF($C$4="Eksempel",COUNTIFS('Eksempel - Risikovurdering'!$S$14:$S$17,"Nej",'Eksempel - Risikovurdering'!$I$14:$I$17,">0"),COUNTIFS(Risikovurdering!$S$17:$S$24,"Nej",Risikovurdering!$I$17:$I$24,">0")) -> 1
B23: 3. Data og informationsaktiver | E23: =IF($C$4="Eksempel",COUNT('Eksempel - Risikovurdering'!$I$19:$I$22),COUNT(Risikovurdering!$I$26:$I$33)) -> 4 | F23: =IF($C$4="Eksempel",COUNTIF('Eksempel - Risikovurdering'!$I$19:$I$22,">=10"),COUNTIF(Risikovurdering!$I$26:$I$33,">=10")) -> 1 | G23: =IF($C$4="Eksempel",IF(COUNT('Eksempel - Risikovurdering'!$I$19:$I$22)=0,"–",AVERAGE('Eksempel - Risikovurdering'!$I$19:$I$22)),IF(COUNT(Risikovurdering!$I$26:$I$33)=0,"–",AVERAGE(Risikovurdering!$I$26:$I$33))) -> 9.5 | H23: =IF($C$4="Eksempel",IF(COUNT('Eksempel - Risikovurdering'!$I$19:$I$22)=0,"–",MAX('Eksempel - Risikovurdering'!$I$19:$I$22)),IF(COUNT(Risikovurdering!$I$26:$I$33)=0,"–",MAX(Risikovurdering!$I$26:$I$33))) -> 15 | J23: =IF($C$4="Eksempel",IF(COUNT('Eksempel - Risikovurdering'!$O$19:$O$22)=0,"–",AVERAGE('Eksempel - Risikovurdering'!$O$19:$O$22)),IF(COUNT(Risikovurdering!$O$26:$O$33)=0,"–",AVERAGE(Risikovurdering!$O$26:$O$33))) -> 4.5 | K23: =IF($C$4="Eksempel",COUNTIF('Eksempel - Risikovurdering'!$O$19:$O$22,">=10"),COUNTIF(Risikovurdering!$O$26:$O$33,">=10")) -> 0 | L23: =IF($C$4="Eksempel",COUNTIF('Eksempel - Risikovurdering'!$Q$19:$Q$22,"Nej"),COUNTIF(Risikovurdering!$Q$26:$Q$33,"Nej")) -> 0 | M23: =IF($C$4="Eksempel",COUNTIFS('Eksempel - Risikovurdering'!$S$19:$S$22,"Nej",'Eksempel - Risikovurdering'!$I$19:$I$22,">0"),COUNTIFS(Risikovurdering!$S$26:$S$33,"Nej",Risikovurdering!$I$26:$I$33,">0")) -> 1
B24: 4. Medarbejdere og processer | E24: =IF($C$4="Eksempel",COUNT('Eksempel - Risikovurdering'!$I$24:$I$27),COUNT(Risikovurdering!$I$35:$I$42)) -> 4 | F24: =IF($C$4="Eksempel",COUNTIF('Eksempel - Risikovurdering'!$I$24:$I$27,">=10"),COUNTIF(Risikovurdering!$I$35:$I$42,">=10")) -> 1 | G24: =IF($C$4="Eksempel",IF(COUNT('Eksempel - Risikovurdering'!$I$24:$I$27)=0,"–",AVERAGE('Eksempel - Risikovurdering'!$I$24:$I$27)),IF(COUNT(Risikovurdering!$I$35:$I$42)=0,"–",AVERAGE(Risikovurdering!$I$35:$I$42))) -> 8 | H24: =IF($C$4="Eksempel",IF(COUNT('Eksempel - Risikovurdering'!$I$24:$I$27)=0,"–",MAX('Eksempel - Risikovurdering'!$I$24:$I$27)),IF(COUNT(Risikovurdering!$I$35:$I$42)=0,"–",MAX(Risikovurdering!$I$35:$I$42))) -> 10 | J24: =IF($C$4="Eksempel",IF(COUNT('Eksempel - Risikovurdering'!$O$24:$O$27)=0,"–",AVERAGE('Eksempel - Risikovurdering'!$O$24:$O$27)),IF(COUNT(Risikovurdering!$O$35:$O$42)=0,"–",AVERAGE(Risikovurdering!$O$35:$O$42))) -> 3.5 | K24: =IF($C$4="Eksempel",COUNTIF('Eksempel - Risikovurdering'!$O$24:$O$27,">=10"),COUNTIF(Risikovurdering!$O$35:$O$42,">=10")) -> 0 | L24: =IF($C$4="Eksempel",COUNTIF('Eksempel - Risikovurdering'!$Q$24:$Q$27,"Nej"),COUNTIF(Risikovurdering!$Q$35:$Q$42,"Nej")) -> 0 | M24: =IF($C$4="Eksempel",COUNTIFS('Eksempel - Risikovurdering'!$S$24:$S$27,"Nej",'Eksempel - Risikovurdering'!$I$24:$I$27,">0"),COUNTIFS(Risikovurdering!$S$35:$S$42,"Nej",Risikovurdering!$I$35:$I$42,">0")) -> 1
B25: 5. Forsyningskæde | E25: =IF($C$4="Eksempel",COUNT('Eksempel - Risikovurdering'!$I$29:$I$32),COUNT(Risikovurdering!$I$44:$I$51)) -> 4 | F25: =IF($C$4="Eksempel",COUNTIF('Eksempel - Risikovurdering'!$I$29:$I$32,">=10"),COUNTIF(Risikovurdering!$I$44:$I$51,">=10")) -> 1 | G25: =IF($C$4="Eksempel",IF(COUNT('Eksempel - Risikovurdering'!$I$29:$I$32)=0,"–",AVERAGE('Eksempel - Risikovurdering'!$I$29:$I$32)),IF(COUNT(Risikovurdering!$I$44:$I$51)=0,"–",AVERAGE(Risikovurdering!$I$44:$I$51))) -> 8 | H25: =IF($C$4="Eksempel",IF(COUNT('Eksempel - Risikovurdering'!$I$29:$I$32)=0,"–",MAX('Eksempel - Risikovurdering'!$I$29:$I$32)),IF(COUNT(Risikovurdering!$I$44:$I$51)=0,"–",MAX(Risikovurdering!$I$44:$I$51))) -> 10 | J25: =IF($C$4="Eksempel",IF(COUNT('Eksempel - Risikovurdering'!$O$29:$O$32)=0,"–",AVERAGE('Eksempel - Risikovurdering'!$O$29:$O$32)),IF(COUNT(Risikovurdering!$O$44:$O$51)=0,"–",AVERAGE(Risikovurdering!$O$44:$O$51))) -> 5 | K25: =IF($C$4="Eksempel",COUNTIF('Eksempel - Risikovurdering'!$O$29:$O$32,">=10"),COUNTIF(Risikovurdering!$O$44:$O$51,">=10")) -> 0 | L25: =IF($C$4="Eksempel",COUNTIF('Eksempel - Risikovurdering'!$Q$29:$Q$32,"Nej"),COUNTIF(Risikovurdering!$Q$44:$Q$51,"Nej")) -> 0 | M25: =IF($C$4="Eksempel",COUNTIFS('Eksempel - Risikovurdering'!$S$29:$S$32,"Nej",'Eksempel - Risikovurdering'!$I$29:$I$32,">0"),COUNTIFS(Risikovurdering!$S$44:$S$51,"Nej",Risikovurdering!$I$44:$I$51,">0")) -> 2
B26: 6. Hændelser og beredskab | E26: =IF($C$4="Eksempel",COUNT('Eksempel - Risikovurdering'!$I$34:$I$37),COUNT(Risikovurdering!$I$53:$I$60)) -> 4 | F26: =IF($C$4="Eksempel",COUNTIF('Eksempel - Risikovurdering'!$I$34:$I$37,">=10"),COUNTIF(Risikovurdering!$I$53:$I$60,">=10")) -> 2 | G26: =IF($C$4="Eksempel",IF(COUNT('Eksempel - Risikovurdering'!$I$34:$I$37)=0,"–",AVERAGE('Eksempel - Risikovurdering'!$I$34:$I$37)),IF(COUNT(Risikovurdering!$I$53:$I$60)=0,"–",AVERAGE(Risikovurdering!$I$53:$I$60))) -> 9 | H26: =IF($C$4="Eksempel",IF(COUNT('Eksempel - Risikovurdering'!$I$34:$I$37)=0,"–",MAX('Eksempel - Risikovurdering'!$I$34:$I$37)),IF(COUNT(Risikovurdering!$I$53:$I$60)=0,"–",MAX(Risikovurdering!$I$53:$I$60))) -> 12 | J26: =IF($C$4="Eksempel",IF(COUNT('Eksempel - Risikovurdering'!$O$34:$O$37)=0,"–",AVERAGE('Eksempel - Risikovurdering'!$O$34:$O$37)),IF(COUNT(Risikovurdering!$O$53:$O$60)=0,"–",AVERAGE(Risikovurdering!$O$53:$O$60))) -> 4.25 | K26: =IF($C$4="Eksempel",COUNTIF('Eksempel - Risikovurdering'!$O$34:$O$37,">=10"),COUNTIF(Risikovurdering!$O$53:$O$60,">=10")) -> 0 | L26: =IF($C$4="Eksempel",COUNTIF('Eksempel - Risikovurdering'!$Q$34:$Q$37,"Nej"),COUNTIF(Risikovurdering!$Q$53:$Q$60,"Nej")) -> 0 | M26: =IF($C$4="Eksempel",COUNTIFS('Eksempel - Risikovurdering'!$S$34:$S$37,"Nej",'Eksempel - Risikovurdering'!$I$34:$I$37,">0"),COUNTIFS(Risikovurdering!$S$53:$S$60,"Nej",Risikovurdering!$I$53:$I$60,">0")) -> 1
B27: I alt | E27: =SUM(E21:E26) -> 25 | F27: =SUM(F21:F26) -> 9 | G27: =IF($C$4="Eksempel",IF(COUNT('Eksempel - Risikovurdering'!$I$7:$I$37)=0,"–",AVERAGE('Eksempel - Risikovurdering'!$I$7:$I$37)),IF(COUNT(Risikovurdering!$I$7:$I$60)=0,"–",AVERAGE(Risikovurdering!$I$7:$I$60))) -> 8.92 | H27: =IF(SUM(E21:E26)=0,"–",MAX(H21:H26)) -> 15 | J27: =IF($C$4="Eksempel",IF(COUNT('Eksempel - Risikovurdering'!$O$7:$O$37)=0,"–",AVERAGE('Eksempel - Risikovurdering'!$O$7:$O$37)),IF(COUNT(Risikovurdering!$O$7:$O$60)=0,"–",AVERAGE(Risikovurdering!$O$7:$O$60))) -> 4.44 | K27: =SUM(K21:K26) -> 0 | L27: =SUM(L21:L26) -> 2 | M27: =SUM(M21:M26) -> 8

Sheet Trusselskatalog
B1: Trusselskatalog
B2: Forslag til trusler og sårbarheder · Brug trussel-ID i kolonnen "Trussel / sårbarhed" i risikovurderingen
B4: Trussel-ID | C4: Trussel / sårbarhed | D4: Beskrivelse
B5: 1. Net- og informationssystemer
B6: T-1.1 | C6: Uautoriseret adgang til netværk | D6: Angribere får adgang til organisationens interne netværk via kompromitterede credentials, VPN-sårbarheder eller fysisk adgang til netværksudstyr.
B7: T-1.2 | C7: DDoS-angreb (Distributed Denial of Service) | D7: Overbelastning af netværksinfrastruktur eller systemer med henblik på at gøre tjenester utilgængelige.
B8: T-1.3 | C8: Mand-i-midten angreb (MITM) | D8: Aflytning eller manipulation af netværkstrafik mellem to parter, f.eks. ved usikrede protokoller eller falske Wi-Fi-adgangspunkter.
B9: T-1.4 | C9: Fejlkonfiguration af netværksudstyr | D9: Fejl i konfiguration af firewalls, routere eller switches medfører utilsigtet eksponering af systemer eller data.
B10: T-1.5 | C10: Uautoriseret brug af trådløse netværk | D10: Uautoriserede enheder kobler sig på det trådløse netværk og kan tilgå interne ressourcer.
B11: T-1.6 | C11: Sårbarhed i netværksprotokoller | D11: Kendte eller ukendte sårbarheder i netværksprotokoller (f.eks. DNS, BGP, SMB) udnyttes til angreb.
B12: T-1.7 | C12: Kompromittering af cloud-infrastruktur | D12: Angribere opnår adgang til organisationens cloud-ressourcer via kompromitterede konti, misconfiguration eller API-sårbarheder.
B13: T-1.8 | C13: Hardwarefejl i kritisk infrastruktur | D13: Fysisk svigt i servere, storage eller netværksudstyr forårsager nedetid og datatab.
B14: T-1.9 | C14: Strømudfald og fysisk skade | D14: Strømudfald, brand, vandskade eller anden fysisk hændelse påvirker tilgængelighed af net- og informationssystemer.
B15: 2. Applikationer og tjenester
B16: T-2.1 | C16: Udnyttelse af softwaresårbarheder | D16: Kendte eller ukendte sårbarheder i applikationer udnyttes til at opnå uautoriseret adgang eller eksekvere kode.
B17: T-2.2 | C17: SQL-injektion og webapplikationsangreb | D17: Angribere injicerer ondsindet kode i webapplikationers input-felter for at manipulere databaser eller omgå adgangskontrol.
B18: T-2.3 | C18: Utilstrækkelig patch-management | D18: Manglende eller forsinket opdatering af software efterlader kendte sårbarheder åbne for udnyttelse.
B19: T-2.4 | C19: Nedbrud af kritiske forretningsapplikationer | D19: Teknisk fejl, overbelastning eller angreb medfører at kritiske applikationer (ERP, CRM, m.fl.) er utilgængelige.
B20: T-2.5 | C20: Usikker API-integration | D20: Dårligt sikrede API'er eksponerer følsomme data eller funktionalitet for uautoriserede parter.
B21: T-2.6 | C21: Misbrug af privilegerede rettigheder i applikationer | D21: Brugere med for brede rettigheder misbruger disse til at tilgå eller ændre data de ikke er autoriserede til.
B22: T-2.7 | C22: E-mail kompromittering (Business Email Compromise) | D22: Angribere overtager eller forfalsker e-mailkonti for at iværksætte svindel, phishing eller spredning af malware.
B23: T-2.8 | C23: Kompromitteret autentifikationssystem | D23: Angreb på autentifikationsinfrastruktur (f.eks. Active Directory, SSO) medfører bred adgang til organisationens systemer.
B24: 3. Data og informationsaktiver
B25: T-3.1 | C25: Datatyveri / eksfiltrering | D25: Følsomme data stjæles og overføres til uvedkommende, f.eks. via malware, insidertrusler eller uautoriseret adgang.
B26: T-3.2 | C26: Ransomware-angreb | D26: Ondsindet software krypterer organisationens data med henblik på afpresning om løsesum.
B27: T-3.3 | C27: Uautoriseret videregivelse af fortrolige oplysninger | D27: Medarbejdere eller tredjeparter deler fortrolige informationer med uvedkommende, tilsigtet eller utilsigtet.
B28: T-3.4 | C28: Datatab som følge af menneskelig fejl | D28: Data slettes, overskrives eller mistes utilsigtet pga. menneskelige fejl uden mulighed for gendannelse.
B29: T-3.5 | C29: Mangelfuld backup og gendannelse | D29: Manglende, fejlende eller utilstrækkelig backup medfører permanent datatab ved hændelse.
B30: T-3.6 | C30: Databrud i cloudlagring | D30: Følsomme data i cloud-opbevaring eksponeres pga. fejlkonfiguration, kompromitterede adgange eller leverandørsvigt.
B31: T-3.7 | C31: Manglende kryptering af følsomme data | D31: Data i transit eller hvile er ikke tilstrækkeligt krypteret og kan tilgås ved aflytning eller uautoriseret adgang.
B32: T-3.8 | C32: Manipulation af data (data integrity angreb) | D32: Angribere ændrer data i systemer eller databaser for at sabotere processer eller skabe falske informationer.
B33: 4. Medarbejdere og processer
B34: T-4.1 | C34: Phishing og social engineering | D34: Medarbejdere manipuleres via falske e-mails, telefonopkald eller beskeder til at afsløre credentials eller installere malware.
B35: T-4.2 | C35: Insider-trussel (tilsigtet) | D35: Medarbejder, tidligere ansat eller konsulent misbruger sin adgang til at skade organisationen bevidst.
B36: T-4.3 | C36: Insider-trussel (utilsigtet / uagtsomhed) | D36: Medarbejder forårsager sikkerhedshændelse ved uforsigtighed, f.eks. fejlsendelse af data, klik på phishing-link eller forkert konfiguration.
B37: T-4.4 | C37: Utilstrækkelig sikkerhedsbevidsthed | D37: Manglende uddannelse og bevidsthed om cybersikkerhed medfører øget risiko for menneskelige fejl og vellykkede angreb.
B38: T-4.5 | C38: Manglende adgangsstyring og offboarding | D38: Adgangsrettigheder opdateres ikke rettidigt ved stillingsskift eller fratrædelse, hvilket giver tidligere ansatte utilsigtet adgang.
B39: T-4.6 | C39: Svage eller kompromitterede adgangskoder | D39: Brug af svage, genbrugte eller kompromitterede adgangskoder øger risikoen for kontoovertagelse.
B40: T-4.7 | C40: Manglende overholdelse af sikkerhedsprocedurer | D40: Medarbejdere omgår eller ignorerer etablerede sikkerhedsprocedurer, f.eks. ved brug af shadow IT eller usikrede enheder.
B41: T-4.8 | C41: Utilstrækkelig adskillelse af arbejdsopgaver | D41: Manglende separation of duties muliggør at én person kan udføre og godkende kritiske handlinger uden kontrol.
...

Sheet Eksempel - Politik
B1: Eksempel: Politik for risikostyring
B2: Forslag til politik, der kan tilpasses egen organisation · NIS2-lovens § 6, stk. 1, nr. 1
B4: 1. FORMÅL
B5: Formålet med denne politik er at etablere en systematisk tilgang til identifikation, analyse, evaluering og håndtering af cybersikkerhedsrisici i overensstemmelse med NIS2-lovens krav. Ved at etablere denne politik sikrer vi: • En ensartet og målrettet risikostyring på tværs af organisationen • Efterlevelse af NIS2-lovens § 6, stk. 1, nr. 1 • At alle relevante risici identificeres og adresseres • At ledelsen har det nødvendige grundlag for beslutninger om cybersikkerhed
B7: 2. RISIKOSTYRINGSPROCES
B8: 2.1 Kontekst og kriterier | C8: Fastlæg rammer for risikovurdering: • Definér scope for risikovurderingen • Identificér kritiske assets og systemer • Fastlæg kriterier for risikoevaluering (risikoappetit) • Identificér risikoejere og deres ansvar
B9: 2.2 Risikoidentifikation | C9: Identificér og dokumentér risici: • Kortlæg alle net- og informationssystemer • Identificér trusler (cybertrusler, menneskelige fejl, miljøpåvirkninger) • Identificér sårbarheder i systemer og processer • Identificér single points of failure • Inkludér risici fra tredjeparter og leverandører
B10: 2.3 Risikoanalyse | C10: Analysér identificerede risici: • Vurdér sandsynlighed for at truslen udnyttes (skala 1-5) • Vurdér konsekvens hvis risikoen indtræffer (skala 1-5) • Beregn risikoscore (sandsynlighed × konsekvens) • Vurdér eksisterende foranstaltningers effektivitet • Dokumentér begrundelser for vurderinger
B11: 2.4 Risikoevaluering | C11: Evaluér risici mod fastsatte kriterier: • Sammenlign risikoscores med risikoappetit • Prioritér risici der kræver handling • Identificér risici der kan accepteres • Godkend risikoevalueringen hos risikoejere
B12: 2.5 Risikohåndtering | C12: Beslut og implementér foranstaltninger: • Reducér: Implementér foranstaltninger til at reducere risiko • Undgå: Stop aktivitet der forårsager risiko • Overfør: Forsikring eller deling med tredjeparter • Acceptér: Dokumentér accept af restrisiko • Udpeg ansvarlig for implementering • Fastsæt tidsplan for implementering
B13: 2.6 Overvågning og revision | C13: Følg op og revurdér løbende: • Overvåg implementering af foranstaltninger • Revurdér risici ved væsentlige ændringer • Gennemfør risikovurdering minimum årligt • Rapportér til ledelsen • Opdatér dokumentation
B14: 3. ROLLER OG ANSVAR
B15: Ledelsesorganet: • Godkender politik for risikostyring • Godkender resultater af risikovurdering og risikohåndteringsplan • Accepterer restrisici • Sikrer ressourcer til implementering af foranstaltninger Risikoejere: • Ansvarlige for specifikke risikoområder • Godkender risikovurderinger for deres område • Beslutter risikohåndtering inden for deres område • Rapporterer til ledelsen IT-sikkerhedsansvarlig: • Faciliterer risikovurderingsprocessen • Vedligeholder risikovurdering og dokumentation • Overvåger implementering af foranstaltninger • Rapporterer til ledelsen om risikostatus
B17: 4. DOKUMENTATION OG REVISION
B18: Denne politik skal: • Dokumenteres og godkendes af ledelsen • Ajourføres minimum årligt • Revideres ved væsentlige ændringer i: - Forretningsmæssig virksomhed - Trusselsbillede - Sårbarheder - Regulatoriske krav • Kommunikeres til relevante medarbejdere • Opbevares tilgængeligt for tilsyn Dokumentation skal omfatte: • Denne politik for risikostyring • Risikovurderingsrapporter • Risikohåndteringsplaner • Godkendelser fra risikoejere og ledelse • Beslutninger om accept af restrisici
B21: GODKENDELSE
B22: Politikken er godkendt af ledelsesorganet:
B23: Navn
B24: Stilling
B25: Dato
B26: Underskrift

Sheet Eksempel - Risikovurdering
A1: Eksempel: Risikovurdering og risikohåndtering
A2: Udfyldt eksempel for en fiktiv mellemstor virksomhed · Vurderingerne er vejledende og skal tilpasses egen organisation
A3: Virksomhed | B3: Eksempelvirksomhed A/S (fiktiv) | E3: Udarbejdet af | G3: IT-chef | I3: Dato | K3: 15-10-2026 | M3: Godkendt af ledelsen (navn/dato) | N3: Direktør, 30-10-2026 | P3: Version | Q3: 1.0 | R3: Hvide felter udfyldes · Grå felter beregnes automatisk
A5: RISIKOVURDERING | M5: RISIKOHÅNDTERING
A6: Risikoområde / aktiv | B6: Trussel / sårbarhed | C6: Risikoejer | D6: Beskrivelse af risiko (hvad kan gå galt?) | E6: Sandsyn- lighed (1-5) | F6: Begrundelse for sandsynlighed (inden for et år) | G6: Konse- kvens (1-5) | H6: Begrundelse for konsekvens | I6: Risiko- score (S×K) | J6: Risiko- niveau | K6: Validitet (1-3) | L6: Accepteres risikoen? | M6: Eksisterende foranstaltninger | N6: Ansvarlig for implementering | O6: Restrisiko (1-25) | P6: Restrisiko- niveau | Q6: Accepteres restrisikoen? | R6: Planlagte foranstaltninger (inden for et år) | S6: Dokumen- tation? | T6: Bemærkninger til vurdering
A7: 1. NET- OG INFORMATIONSSYSTEMER
A8: Servere og hosting-infrastruktur | B8: T-2.3 Uopdateret eller usikret server | C8: IT-chef | D8: Servere kan blive kompromitteret og give angribere adgang til data og systemer | E8: 2 | F8: Der er implementeret automatisk patch management for kritiske servere, og der gennemføres kvartalsvise sårbarhedsscanninger. Ingen kritiske sårbarheder har stået åbne i mere end 30 dage det seneste år. | G8: 4 | H8: Serverne hoster bl.a. ERP-system og kundedata. En kompromittering kan medføre driftsstop og forsinkede leverancer til kunder med betydelige økonomiske og omdømmemæssige konsekvenser. | I8: =IF(OR(E8="",G8=""),"",E8*G8) -> 8 | J8: =IF(I8="","",IF(I8<5,"Lav",IF(I8<10,"Middel","Høj"))) -> Middel | K8: 3 | L8: Ja | M8: Segmenteret servernetværk, antivirus/EDR på alle servere, automatisk patching af OS, kvartalsvise sårbarhedsscanninger, adgang kun via VPN og MFA. | N8: IT-chef | O8: 4 | P8: =IF(O8="","",IF(O8<5,"Lav",IF(O8<10,"Middel","Høj"))) -> Lav | Q8: Ja | R8: Implementering af centraliseret log-overvågning (SIEM) og overgang til månedlig sårbarhedsscanning inden udgangen af Q2. | S8: Ja | T8: Sidst testet ved intern sårbarhedsscanning marts 2026. Revurderes ved næste scanning.
A9: Netværksudstyr (firewalls, switches, routere) | B9: T-1.4 Fejlkonfiguration af netværksudstyr | C9: IT-chef | D9: Netværket kan blive kompromitteret og give uautoriseret adgang | E9: 2 | F9: Netværksudstyr konfigureres efter dokumenteret baseline, og der er ikke konstateret uautoriserede konfigurationsændringer de seneste 12 måneder. | G9: 4 | H9: Netværket forbinder administrative systemer med driftsnetværket (OT). En kompromittering af netværksudstyr kan give angribere adgang til styresystemer og forstyrre kritiske leverancer. | I9: =IF(OR(E9="",G9=""),"",E9*G9) -> 8 | J9: =IF(I9="","",IF(I9<5,"Lav",IF(I9<10,"Middel","Høj"))) -> Middel | K9: 2 | L9: Nej | M9: Firewallregler gennemgås årligt, netværkssegmentering mellem IT og OT, ændringer logges. | N9: IT-chef | O9: 5 | P9: =IF(O9="","",IF(O9<5,"Lav",IF(O9<10,"Middel","Høj"))) -> Middel | Q9: Ja | R9: Indførelse af automatisk konfigurationsbackup og halvårlig ekstern penetrationstest af netværksperimeteret. | S9: Ja | T9: Netværksdiagram opdateret januar 2026. OT/IT-segmenteringen bør verificeres af ekstern rådgiver.
A10: Cloudtjenester | B10: T-1.7 Kompromittering af cloud-infrastruktur | C10: IT-chef | D10: Data kan blive eksponeret, eller tjenester kan blive utilgængelige | E10: 3 | F10: Virksomheden anvender flere cloudtjenester (bl.a. til ERP og lagerstyring) uden ensartet gennemgang af leverandørernes sikkerhedscertificeringer. | G10: 4 | H10: Et brud hos cloududbyderen kan eksponere kunde- og leverandørdata og afbryde adgangen til forretningskritiske systemer i driftstiden. | I10: =IF(OR(E10="",G10=""),"",E10*G10) -> 12 | J10: =IF(I10="","",IF(I10<5,"Lav",IF(I10<10,"Middel","Høj"))) -> Høj | K10: 2 | L10: Nej | M10: MFA på alle cloudkonti, gennemgang af leverandørers ISO 27001-certificering ved indgåelse af nye aftaler. | N10: IT-chef | O10: 6 | P10: =IF(O10="","",IF(O10<5,"Lav",IF(O10<10,"Middel","Høj"))) -> Middel | Q10: Nej | R10: Formel cloud-sikkerhedspolitik, årlig revurdering af databehandleraftaler (DPA) og exitplan for kritiske cloudtjenester. | S10: Nej | T10: Databehandleraftaler for 2 ud af 5 cloudleverandører mangler opdatering. Følges op af IT og jura inden 1. juli 2027.
A11: Endpoints (pc, mobil, tablet) | B11: T-4.1 Phishing / manglende endpoint-beskyttelse | C11: IT-chef | D11: Enheder kan inficeres med malware og bruges som indgangsvektor | E11: 3 | F11: Medarbejderne arbejder hybridt, og der registreres ugentligt phishing-forsøg. Ikke alle mobile enheder er under central styring. | G11: 3 | H11: Inficerede endpoints kan bruges som indgang til virksomhedens netværk og medføre spredning af malware til administrative systemer. | I11: =IF(OR(E11="",G11=""),"",E11*G11) -> 9 | J11: =IF(I11="","",IF(I11<5,"Lav",IF(I11<10,"Middel","Høj"))) -> Middel | K11: 2 | L11: Nej | M11: EDR/antivirus på alle firmaenheder, automatisk skærmlås, kryptering af harddiske. | N11: IT-chef | O11: 4 | P11: =IF(O11="","",IF(O11<5,"Lav",IF(O11<10,"Middel","Høj"))) -> Lav | Q11: Ja | R11: Implementering af Mobile Device Management (MDM), der også dækker private enheder (BYOD), inden udgangen af året. | S11: Ja | T11: Ca. 15 % af medarbejderne anvender i dag ikke-styrede private enheder til tjenstlig kommunikation.
A12: Industrielle styresystemer (OT, f.eks. SCADA/PLC) | B12: T-2.3 Manglende opdatering og segmentering af OT-udstyr | C12: Driftschef | D12: Kompromittering af styresystemer kan medføre driftsstop, fejl i leverancer eller hændelser med betydning for person- og forsyningssikkerhed | E12: 2 | F12: OT-udstyret er ældre og opdateres sjældent på grund af krav om driftsstabilitet. Der er dog etableret fysisk adgangskontrol til driftsområderne. | G12: 5 | H12: Styresystemerne understøtter virksomhedens kerneleverance. Et angreb kan stoppe driften i flere dage og i værste fald forårsage fysiske skader med samfundsmæssige konsekvenser. | I12: =IF(OR(E12="",G12=""),"",E12*G12) -> 10 | J12: =IF(I12="","",IF(I12<5,"Lav",IF(I12<10,"Middel","Høj"))) -> Høj | K12: 1 | L12: Nej | M12: Fysisk adskilt driftsnetværk (delvis segmentering), adgangskoder på HMI-paneler, begrænset fjernadgang for leverandører. | N12: Driftschef i samarbejde med IT-chef | O12: 4 | P12: =IF(O12="","",IF(O12<5,"Lav",IF(O12<10,"Middel","Høj"))) -> Lav | Q12: Nej | R12: Fuld netværkssegmentering mellem IT og OT (jf. IEC 62443), overvågning af OT-netværkstrafik og opdatering af ældste PLC-firmware inden udgangen af 2027. | S12: Nej | T12: Der er endnu ikke gennemført en formel OT-sikkerhedsvurdering, derfor lav validitet. Anbefales prioriteret højt pga. den direkte kobling til kerneleverancen.
A13: 2. APPLIKATIONER OG TJENESTER
A14: Forretningskritiske applikationer (ERP, CRM) | B14: T-2.1 Udnyttelse af softwaresårbarheder | C14: Økonomichef | D14: Sårbarheder i ERP/CRM kan udnyttes til uautoriseret adgang eller forstyrre ordre- og fakturaflowet | E14: 2 | F14: ERP leveres som SaaS med leverandørstyret patching. Ingen kendte hændelser de seneste tre år. | G14: 4 | H14: ERP understøtter ordre, lager og fakturering. Nedetid på mere end én dag giver forsinkede leverancer og likviditetstab. | I14: =IF(OR(E14="",G14=""),"",E14*G14) -> 8 | J14: =IF(I14="","",IF(I14<5,"Lav",IF(I14<10,"Middel","Høj"))) -> Middel | K14: 2 | L14: Nej | M14: SaaS-løsning med leverandørens sikkerhedsopdateringer, MFA for alle brugere, rollebaserede rettigheder. | N14: IT-chef | O14: 4 | P14: =IF(O14="","",IF(O14<5,"Lav",IF(O14<10,"Middel","Høj"))) -> Lav | Q14: Ja | R14: Kvartalsvis gennemgang af brugerrettigheder og test af nødprocedure for manuel ordrehåndtering. | S14: Ja | T14: Leverandørens SOC 2-rapport gennemgået august 2026.
A15: E-mailsystem | B15: T-2.7 E-mailkompromittering (BEC) | C15: IT-chef | D15: Overtagelse af en e-mailkonto kan bruges til fakturasvindel og spredning af phishing til kunder | E15: 4 | F15: Virksomheden modtager dagligt phishing-forsøg, og der er registreret to forsøg på fakturasvindel det seneste år. | G15: 3 | H15: Økonomisk tab ved fejlbetalinger og skade på kunders tillid. Begrænset påvirkning af driften. | I15: =IF(OR(E15="",G15=""),"",E15*G15) -> 12 | J15: =IF(I15="","",IF(I15<5,"Lav",IF(I15<10,"Middel","Høj"))) -> Høj | K15: 3 | L15: Nej | M15: Spamfilter med sandboxing, MFA, DMARC/DKIM/SPF, procedure for telefonisk verifikation af ændrede kontooplysninger. | N15: IT-chef | O15: 6 | P15: =IF(O15="","",IF(O15<5,"Lav",IF(O15<10,"Middel","Høj"))) -> Middel | Q15: Ja | R15: Kvartalsvise phishing-simuleringer og blokering af ældre autentifikationsprotokoller. | S15: Ja | T15: Antal registrerede phishing-forsøg følges månedligt.
A16: Webshop og kundeportal | B16: T-2.2 SQL-injektion og webapplikationsangreb | C16: E-commercechef | D16: Angribere kan tilgå kundedata eller sætte webshoppen ud af drift | E16: 3 | F16: Webshoppen er eksponeret mod internettet og udsættes løbende for automatiserede angreb. Seneste penetrationstest fandt to middelalvorlige fund. | G16: 4 | H16: Webshoppen står for ca. 30 % af omsætningen. Et brud på kundedata medfører anmeldelse til Datatilsynet og omdømmeskade. | I16: =IF(OR(E16="",G16=""),"",E16*G16) -> 12 | J16: =IF(I16="","",IF(I16<5,"Lav",IF(I16<10,"Middel","Høj"))) -> Høj | K16: 2 | L16: Nej | M16: Web application firewall (WAF), årlig penetrationstest, sikker udviklingsproces hos leverandøren. | N16: E-commercechef i samarbejde med IT-chef | O16: 6 | P16: =IF(O16="","",IF(O16<5,"Lav",IF(O16<10,"Middel","Høj"))) -> Middel | Q16: Ja | R16: Lukning af fund fra penetrationstesten inden 1. december 2026 og indførelse af løbende sårbarhedsscanning. | S16: Ja | T16: Fund fra penetrationstesten følges i leverandørens ticketsystem.
A17: Integrationer og API'er | B17: T-2.5 Usikker API-integration | C17: IT-chef | D17: Dårligt sikrede integrationer kan eksponere data eller give adgang til bagvedliggende systemer | E17: 2 | F17: Der er få integrationer, og de er dokumenteret, men API-nøgler roteres ikke fast. | G17: 3 | H17: Begrænset datamængde kan eksponeres. Ingen direkte påvirkning af driften. | I17: =IF(OR(E17="",G17=""),"",E17*G17) -> 6 | J17: =IF(I17="","",IF(I17<5,"Lav",IF(I17<10,"Middel","Høj"))) -> Middel | K17: 2 | L17: Ja | M17: API-nøgler opbevares i nøgleboks, adgang er begrænset til kendte IP-adresser. | N17: IT-chef | O17: 3 | P17: =IF(O17="","",IF(O17<5,"Lav",IF(O17<10,"Middel","Høj"))) -> Lav | Q17: Ja | R17: Fast rotation af API-nøgler hver 6. måned. | S17: Nej
A18: 3. DATA OG INFORMATIONSAKTIVER
A19: Kundedata og personoplysninger | B19: T-3.1 Datatyveri / eksfiltrering | C19: Databeskyttelsesansvarlig | D19: Læk af personoplysninger medfører brud på GDPR og tab af kundetillid | E19: 2 | F19: Data er samlet i få systemer med adgangsstyring. Ingen kendte brud. | G19: 4 | H19: Anmeldelse til Datatilsynet, risiko for bøde og betydelig omdømmeskade. | I19: =IF(OR(E19="",G19=""),"",E19*G19) -> 8 | J19: =IF(I19="","",IF(I19<5,"Lav",IF(I19<10,"Middel","Høj"))) -> Middel | K19: 2 | L19: Nej | M19: Rollebaseret adgang, kryptering af databaser, logning af adgang til persondata. | N19: Databeskyttelsesansvarlig | O19: 4 | P19: =IF(O19="","",IF(O19<5,"Lav",IF(O19<10,"Middel","Høj"))) -> Lav | Q19: Ja | R19: Implementering af DLP-regler i Microsoft 365 og årlig gennemgang af slettepolitikken. | S19: Ja
A20: Forretningskritiske data | B20: T-3.2 Ransomware-angreb | C20: IT-chef | D20: Kryptering af data og systemer kan stoppe driften og medføre datatab | E20: 3 | F20: Ransomware er en af de mest udbredte trusler mod danske virksomheder. Virksomheden har ikke tidligere været ramt. | G20: 5 | H20: Fuldt driftsstop i op til en uge og risiko for permanent tab af data, der ikke er sikkerhedskopieret. | I20: =IF(OR(E20="",G20=""),"",E20*G20) -> 15 | J20: =IF(I20="","",IF(I20<5,"Lav",IF(I20<10,"Middel","Høj"))) -> Høj | K20: 2 | L20: Nej | M20: Daglig backup med offline kopi, EDR på alle enheder, segmenteret netværk. | N20: IT-chef | O20: 6 | P20: =IF(O20="","",IF(O20<5,"Lav",IF(O20<10,"Middel","Høj"))) -> Middel | Q20: Ja | R20: Halvårlig fuld genetableringstest og indførelse af uforanderlig (immutable) backup. | S20: Ja | T20: Seneste genetableringstest i maj 2026: ERP var genetableret efter 14 timer.
A21: Forretningshemmeligheder | B21: T-3.3 Uautoriseret videregivelse af fortrolige oplysninger | C21: Direktør | D21: Tab af tegninger, priser eller tilbudsmateriale kan svække konkurrenceevnen | E21: 2 | F21: Fortrolige data deles i stigende grad med samarbejdspartnere via e-mail og delte mapper. | G21: 3 | H21: Økonomisk skade på længere sigt, men ingen direkte driftspåvirkning. | I21: =IF(OR(E21="",G21=""),"",E21*G21) -> 6 | J21: =IF(I21="","",IF(I21<5,"Lav",IF(I21<10,"Middel","Høj"))) -> Middel | K21: 1 | L21: Ja | M21: Klassifikation af dokumenter, fortrolighedsaftaler med samarbejdspartnere. | N21: Direktør | O21: 4 | P21: =IF(O21="","",IF(O21<5,"Lav",IF(O21<10,"Middel","Høj"))) -> Lav | Q21: Ja | R21: Kvartalsvis gennemgang af eksterne delinger i SharePoint. | S21: Nej | T21: Vurderingen er et skøn, da omfanget af ekstern deling ikke er kortlagt.
A22: Logfiler og auditspor | B22: T-6.7 Utilstrækkelig logging og auditspor | C22: IT-chef | D22: Manglende logs gør det umuligt at efterforske hændelser og dokumentere compliance | E22: 3 | F22: Logning er aktiveret på servere og cloud, men logs gemmes kun i 30 dage og gennemgås ikke systematisk. | G22: 3 | H22: Forsinket opdagelse af hændelser og manglende dokumentation over for tilsynsmyndigheden. | I22: =IF(OR(E22="",G22=""),"",E22*G22) -> 9 | J22: =IF(I22="","",IF(I22<5,"Lav",IF(I22<10,"Middel","Høj"))) -> Middel | K22: 2 | L22: Nej | M22: Central logning af cloudtjenester og firewalls. | N22: IT-chef | O22: 4 | P22: =IF(O22="","",IF(O22<5,"Lav",IF(O22<10,"Middel","Høj"))) -> Lav | Q22: Ja | R22: Forlængelse af opbevaringen til 12 måneder og etablering af SIEM (jf. risikoen for servere). | S22: Ja
A23: 4. MEDARBEJDERE OG PROCESSER
A24: Medarbejdernes sikkerhedsbevidsthed | B24: T-4.4 Utilstrækkelig sikkerhedsbevidsthed | C24: HR-chef | D24: Medarbejdere kan utilsigtet forårsage sikkerhedshændelser | E24: 3 | F24: Awareness-træning er kun gennemført for administrative medarbejdere. Klikraten ved seneste phishing-test var 11 %. | G24: 3 | H24: Øget sandsynlighed for vellykket phishing og malware med afledte driftsforstyrrelser. | I24: =IF(OR(E24="",G24=""),"",E24*G24) -> 9 | J24: =IF(I24="","",IF(I24<5,"Lav",IF(I24<10,"Middel","Høj"))) -> Middel | K24: 3 | L24: Nej | M24: Årlig e-learning for administrative medarbejdere. | N24: HR-chef | O24: 4 | P24: =IF(O24="","",IF(O24<5,"Lav",IF(O24<10,"Middel","Høj"))) -> Lav | Q24: Ja | R24: Obligatorisk træning for alle medarbejdere og kvartalsvise phishing-simuleringer. | S24: Ja | T24: Mål: klikrate under 5 % inden udgangen af 2027.
A25: Adgangsstyring og offboarding | B25: T-4.5 Manglende adgangsstyring og offboarding | C25: HR-chef | D25: Tidligere medarbejdere eller konsulenter kan bevare adgang til systemer | E25: 3 | F25: Seneste gennemgang fandt fire aktive konti tilhørende fratrådte medarbejdere. | G25: 3 | H25: Uautoriseret adgang til data og systemer med risiko for misbrug. | I25: =IF(OR(E25="",G25=""),"",E25*G25) -> 9 | J25: =IF(I25="","",IF(I25<5,"Lav",IF(I25<10,"Middel","Høj"))) -> Middel | K25: 3 | L25: Nej | M25: Tjekliste ved fratrædelse, MFA på alle konti. | N25: IT-chef | O25: 3 | P25: =IF(O25="","",IF(O25<5,"Lav",IF(O25<10,"Middel","Høj"))) -> Lav | Q25: Ja | R25: Automatisk lukning af konti via kobling mellem HR-system og brugerkatalog samt kvartalsvis rettighedsgennemgang. | S25: Ja
A26: Privilegerede konti | B26: T-2.6 Misbrug af privilegerede rettigheder | C26: IT-chef | D26: Kompromittering af en administratorkonto giver bred adgang til hele it-miljøet | E26: 2 | F26: Antallet af administratorkonti er reduceret, men to servicekonti har stadig domæneadministratorrettigheder. | G26: 5 | H26: En kompromitteret administratorkonto kan bruges til at lamme alle systemer. | I26: =IF(OR(E26="",G26=""),"",E26*G26) -> 10 | J26: =IF(I26="","",IF(I26<5,"Lav",IF(I26<10,"Middel","Høj"))) -> Høj | K26: 2 | L26: Nej | M26: Separate administratorkonti, MFA, logning af administratoraktivitet. | N26: IT-chef | O26: 5 | P26: =IF(O26="","",IF(O26<5,"Lav",IF(O26<10,"Middel","Høj"))) -> Middel | Q26: Ja | R26: Indførelse af Privileged Access Management (PAM) og fjernelse af overflødige rettigheder fra servicekonti. | S26: Ja
A27: Sikkerhedsprocedurer i hverdagen | B27: T-4.7 Manglende overholdelse af sikkerhedsprocedurer | C27: Direktør | D27: Procedurer omgås, f.eks. via shadow IT eller deling af adgangskoder | E27: 2 | F27: Enkelte afdelinger anvender egne cloudtjenester uden godkendelse fra IT. | G27: 2 | H27: Begrænset konsekvens, men øger angrebsfladen og risikoen for datalæk. | I27: =IF(OR(E27="",G27=""),"",E27*G27) -> 4 | J27: =IF(I27="","",IF(I27<5,"Lav",IF(I27<10,"Middel","Høj"))) -> Lav | K27: 1 | L27: Ja | M27: IT-sikkerhedspolitik og regler for acceptabel brug underskrevet af alle medarbejdere. | N27: IT-chef | O27: 2 | P27: =IF(O27="","",IF(O27<5,"Lav",IF(O27<10,"Middel","Høj"))) -> Lav | Q27: Ja | R27: Kortlægning af ikke-godkendte cloudtjenester. | S27: Nej
A28: 5. FORSYNINGSKÆDE
A29: IT-driftsleverandør | B29: T-5.2 Svag sikkerhed hos kritiske leverandører | C29: IT-chef | D29: Leverandørens fjernadgang kan misbruges som indgang til virksomhedens systemer | E29: 2 | F29: Leverandøren er ISO 27001-certificeret, men har bred fjernadgang døgnet rundt. | G29: 5 | H29: En kompromittering hos leverandøren kan give fuld adgang til alle systemer. | I29: =IF(OR(E29="",G29=""),"",E29*G29) -> 10 | J29: =IF(I29="","",IF(I29<5,"Lav",IF(I29<10,"Middel","Høj"))) -> Høj | K29: 2 | L29: Nej | M29: Databehandleraftale, MFA på leverandørkonti, årlig gennemgang af ISO-certifikat. | N29: IT-chef | O29: 6 | P29: =IF(O29="","",IF(O29<5,"Lav",IF(O29<10,"Middel","Høj"))) -> Middel | Q29: Ja | R29: Tidsbegrænset fjernadgang (just-in-time) og overvågning af leverandørsessioner. | S29: Ja
A30: Softwareleverandører | B30: T-5.1 Kompromitteret softwareleverandør | C30: IT-chef | D30: Kompromitterede opdateringer fra en leverandør kan installere malware | E30: 1 | F30: Sjælden hændelse, men set i større internationale angreb. | G30: 5 | H30: Malware kan sprede sig til alle enheder via legitime opdateringskanaler. | I30: =IF(OR(E30="",G30=""),"",E30*G30) -> 5 | J30: =IF(I30="","",IF(I30<5,"Lav",IF(I30<10,"Middel","Høj"))) -> Middel | K30: 1 | L30: Ja | M30: EDR overvåger også adfærd fra signeret software. | N30: IT-chef | O30: 4 | P30: =IF(O30="","",IF(O30<5,"Lav",IF(O30<10,"Middel","Høj"))) -> Lav | Q30: Ja | R30: Krav om oplysninger om softwarekomponenter (SBOM) ved indkøb af ny kritisk software. | S30: Nej | T30: Lav sandsynlighed, men høj konsekvens. Følges via trusselsinformation.
A31: Leverandørkontrakter | B31: T-5.3 Utilstrækkelig kontraktlig sikkerhedsstyring | C31: Indkøbschef | D31: Uklare sikkerhedskrav i kontrakter giver uklar ansvarsfordeling ved hændelser | E31: 3 | F31: Kun 40 % af kontrakterne med kritiske leverandører indeholder sikkerhedskrav og krav om underretning ved hændelser. | G31: 3 | H31: Forsinket håndtering og uklart ansvar ved hændelser hos leverandører. | I31: =IF(OR(E31="",G31=""),"",E31*G31) -> 9 | J31: =IF(I31="","",IF(I31<5,"Lav",IF(I31<10,"Middel","Høj"))) -> Middel | K31: 3 | L31: Nej | M31: Standardkontrakt med sikkerhedsbilag for nye leverandører. | N31: Indkøbschef | O31: 4 | P31: =IF(O31="","",IF(O31<5,"Lav",IF(O31<10,"Middel","Høj"))) -> Lav | Q31: Ja | R31: Genforhandling af kontrakter med de ti mest kritiske leverandører inden udgangen af 2027. | S31: Ja | T31: Leverandøroversigt med kritikalitet opdateret september 2026.
A32: Kritiske underleverandører | B32: T-5.4 Svigt hos kritisk underleverandør | C32: Driftschef | D32: Svigt hos en kritisk underleverandør kan stoppe egne leverancer | E32: 2 | F32: Få leverandører er eneleverandører, men alternativer er ikke kortlagt. | G32: 4 | H32: Forsinkede leverancer til kunder i op til flere uger. | I32: =IF(OR(E32="",G32=""),"",E32*G32) -> 8 | J32: =IF(I32="","",IF(I32<5,"Lav",IF(I32<10,"Middel","Høj"))) -> Middel | K32: 1 | L32: Nej | M32: Dialog med de vigtigste leverandører om deres beredskab. | N32: Driftschef | O32: 6 | P32: =IF(O32="","",IF(O32<5,"Lav",IF(O32<10,"Middel","Høj"))) -> Middel | Q32: Ja | R32: Kortlægning af eneleverandører og aftaler med alternative leverandører. | S32: Nej
A33: 6. HÆNDELSER OG BEREDSKAB
